<?xml version="1.0" ?>
<!-- =================================================================================== -->
<!-- |    This document was autogenerated by xacro from src/robot_description/urdf/robot_description.xacro | -->
<!-- |    EDITING THIS FILE BY HAND IS NOT RECOMMENDED                                 | -->
<!-- =================================================================================== -->
<!-- https://wiki.ros.org/urdf/XML/link -->
<robot name="soldador">
  <!-- Definindo Cores -->
  <material name="red">
    <color rgba="0.8 0 0 1"/>
  </material>
  <material name="green">
    <color rgba="0 0.8 0 1"/>
  </material>
  <material name="blue">
    <color rgba="0 0 0.8 1"/>
  </material>
  <material name="yellow">
    <color rgba="1 1 0 1"/>
  </material>
  <material name="cyan">
    <color rgba="0 1 1 1"/>
  </material>
  <link name="world">
    <visual>
      <geometry>
        <box size="0.1 0.1 0.1"/>
      </geometry>
      <origin rpy="0 0 0" xyz="0 0 0"/>
      <material name="green"/>
    </visual>
  </link>
  <joint name="joint_0" type="fixed">
    <parent link="world"/>
    <child link="base_link"/>
    <origin rpy="0 0 0" xyz="0 0 0.23"/>
  </joint>
  <link name="base_link">
    <visual>
      <geometry>
        <mesh filename="package://robot_description/meshes/base_link.STL"/>
      </geometry>
      <origin rpy="0 0 0" xyz="0 0 0"/>
      <material name="green"/>
    </visual>
  </link>
  <joint name="joint_1" type="revolute">
    <parent link="base_link"/>
    <child link="link_1"/>
    <origin rpy="-1.5708 0 1.3815" xyz="-0.12618 0 0.31169"/>
    <axis xyz="0 1 0"/>
    <limit effort="1000" lower="-3.141593" upper="3.141593" velocity="0.5"/>
  </joint>
  <link name="link_1">
    <visual>
      <geometry>
        <mesh filename="package://robot_description/meshes/link_1.STL"/>
      </geometry>
      <origin rpy="0 0 0" xyz="0 0 0"/>
      <material name="yellow"/>
    </visual>
  </link>
  <joint name="joint_2" type="revolute">
    <parent link="link_1"/>
    <child link="link_2"/>
    <origin rpy="3.0346 0 0" xyz="-0.14641 -0.08128 0"/>
    <axis xyz="1 0 0"/>
    <limit effort="1000" lower="-1.5707" upper="1.5707" velocity="0.5"/>
  </joint>
  <link name="link_2">
    <visual>
      <geometry>
        <mesh filename="package://robot_description/meshes/link_2.STL"/>
      </geometry>
      <origin rpy="0 0 0" xyz="0 0 0"/>
      <material name="red"/>
    </visual>
  </link>
  <joint name="joint_3" type="revolute">
    <parent link="link_2"/>
    <child link="link_3"/>
    <origin rpy="-2.6879 0 -3.1416" xyz="0 0 0.4318"/>
    <axis xyz="1 0 0"/>
    <limit effort="1000" lower="-1.5707" upper="1.5707" velocity="0.5"/>
  </joint>
  <link name="link_3">
    <visual>
      <geometry>
        <mesh filename="package://robot_description/meshes/link_3.STL"/>
      </geometry>
      <origin rpy="0 0 0" xyz="0 0 0"/>
      <material name="red"/>
    </visual>
  </link>
  <joint name="joint_4" type="revolute">
    <parent link="link_3"/>
    <child link="link_4"/>
    <origin rpy="3.1416 -1.2686 3.1416" xyz="-0.016872 -0.39296 0"/>
    <axis xyz="0 1 0"/>
    <limit effort="1000" lower="-1.5707" upper="1.5707" velocity="0.5"/>
  </joint>
  <link name="link_4">
    <visual>
      <geometry>
        <mesh filename="package://robot_description/meshes/link_4.STL"/>
      </geometry>
      <origin rpy="0 0 0" xyz="0 0 0"/>
      <material name="yellow"/>
    </visual>
  </link>
  <joint name="joint_5" type="revolute">
    <parent link="link_4"/>
    <child link="link_5"/>
    <origin rpy="1.4855 1.5708 0" xyz="0 -0.039129 0"/>
    <axis xyz="1 0 0"/>
    <limit effort="1000" lower="-1.5707" upper="1.5707" velocity="0.5"/>
  </joint>
  <link name="link_5">
    <visual>
      <geometry>
        <mesh filename="package://robot_description/meshes/link_5.STL"/>
      </geometry>
      <origin rpy="0 0 0" xyz="0 0 0"/>
      <material name="yellow"/>
    </visual>
  </link>
</robot>
